Workbook
Name _______xx145: #REF!
Name _______xx145: #REF!
Name _____xx145: #REF!
Name _____xx145: #REF!
Name ___xx145: #REF!
Name ___xx145: #REF!
Name __xx145: #REF!
Name __xx145: #REF!
Name _1___11: #REF!
Name _1___11: #REF!
Name _1___11_1: NA()
Name _1__11: #REF!
Name _1__11: #REF!
Name _1_Excel_BuiltIn_Print_Area_1_1: #REF!
Name _1_Excel_BuiltIn_Print_Area_1_1: #REF!
Name _19___20: #REF!
Name _19___20: #REF!
Name _19___20_1: NA()
Name _1Excel_BuiltIn_Print_Area_1_1: #REF!
Name _1Excel_BuiltIn_Print_Area_1_1: #REF!
Name _2: #REF!
Name _2: #REF!
Name _2_Excel_BuiltIn_Print_Area_6_1: #REF!
Name _2_Excel_BuiltIn_Print_Area_6_1: #REF!
Name _2Excel_BuiltIn_Print_Area_6_1: #REF!
Name _2Excel_BuiltIn_Print_Area_6_1: #REF!
Name _32._Nomes_dos_colaboradores__que_compõe_esse_GHE: '[1]APR BASE'!#REF!
Name _32._Nomes_dos_colaboradores__que_compõe_esse_GHE: '[1]APR BASE'!#REF!
Name _32._Nomes_dos_colaboradores__que_compõe_esse_GHE_1: NA()
Name _33._Matrícula: '[1]APR BASE'!#REF!
Name _33._Matrícula: '[1]APR BASE'!#REF!
Name _33._Matrícula_1: NA()
Name _34._Função: '[1]APR BASE'!#REF!
Name _34._Função: '[1]APR BASE'!#REF!
Name _34._Função_1: NA()
Name _xx145: #REF!
Name _xx145: #REF!
Name a: #REF!
Name a: #REF!
Name a\sx\xz\: #REF!
Name a\sx\xz\: #REF!
Name AA: #REF!
Name AA: #REF!
Name AAAAA: #REF!
Name AAAAA: #REF!
Name aassxa__: #REF!
Name aassxa__: #REF!
Name Agentes: Plan1!$A$1:$A$267
Name ANDAR: #REF!
Name ANDAR: #REF!
Name ANDAR_1: NA()
Name AQ: #REF!
Name AQ: #REF!
Name asas: #REF!
Name asas: #REF!
Name asd: #REF!
Name asd: #REF!
Name ASDADA: #REF!
Name ASDADA: #REF!
Name ASDASD: #REF!

Sheet Dados Empresa
G2: FORMULÁRIO PARA SOLICITAÇÃO DE ANÁLISE DE AMOSTRAS DE HIGIENE OCUPACIONAL | P2: Código: | Q2: IT02-M
P3: Revisão: | Q3: 11
P4: Data da Revisão | Q4: 45478
G5: FORMATO ELETRÔNICO PARA IMPORTAÇÃO
D7: DATA DO ENVIO: | I7: DATA DE RECEBIMENTO NO LAB.:
B9: NÚMERO DO ORÇAMENTO:
B10: EMPRESA CONTRATANTE
B11: (*) RAZÃO SOCIAL: | D11: • ASSISTE ENGENHARIA DE SEGURANÇA DO TRABALHO LTDA.
B12: (*) CNPJ/CPF: | D12: 03.053.305/0001-50 | J12: (*) CIDADE:
B13: (*) ENDEREÇO:
B14: (*) Nº | E14: BAIRRO: | F14: Lourdes | J14: UF: | L14: MG
B15: PESSOA CONTATO: | D15: Bernardo Junqueira | J15: (*) CEP: | L15: 30.130-922
B16: (*) FONE: | D16: (31) 97157-3642 / (31) 3514-0405 | J16: (*) E-MAIL : | L16: bernardojunqueira@ocupacional.com.br / suporteengenharia@ocupacional.com.br / contasapagar@ocupacional.com.br
B18: EMPRESA AVALIADA
B19: (*) RAZÃO SOCIAL:
B20: (*) CNPJ/CPF: | J20: (*) CIDADE:
B21: (*) ENDEREÇO:
B22: (*) Nº | E22: BAIRRO: | J22: UF:
B23: PESSOA CONTATO: | J23: (*) CEP:
B24: (*) FONE: | J24: (*) E-MAIL :
B26: (*) RELATÓRIO DE ANÁLISE DEVE SER ENVIADO PARA: | G26: ( ) | H26: CONTRATANTE | J26: ( ) | K26: AVALIADA | M26: ( ) | N26: OUTRO: | O26: _______________________
B27: E-MAIL:
B29: (*) FATURAMENTO DEVERÁ SER FEITO: | G29: ( ) | H29: CONTRATANTE | J29: ( ) | K29: AVALIADA | M29: ( ) | N29: OUTRO: | O29: _______________________
B30: E-MAIL FINANCEIRO:
B32: URGÊNCIA
B33: (Consultar as condições técnicas / valor da urgência antecipadamente com o laboratório)
B34: Data e hora requerida:
B36: Campos marcados com (*) são obrigatórios para solicitação de análise.
B37: O prazo de entrega dos resultados será contado a partir do recebimento das informações obrigatórias acima.
B38: Amostras enviadas sem as informações acima serão descartadas após 30 dias e será cobrado o custo dos amostradores.
B39: Todas as informações das empresas são seguidas de acordo com o site da receita federal. Caso endereço de amostragem seja diferente do site da receita federal, o mesmo constará no campo de observações no rodapé dos relatórios
B41: UniScientific Group Ltda - Rua Benedito Conrado Filho nº225/233 - Jardim Beatriz - São Bernardo do Campo - SP - CEP: 09895-110 - Fone: 11 2381-3958 / 11 2381-3957

Sheet Dados Agentes
B1: FORMULÁRIO PARA SOLICITAÇÃO DE ANÁLISE DE AMOSTRAS DE HIGIENE OCUPACIONAL | L1: Código | M1: ='Dados Empresa'!Q2 -> IT02-M
L2: Revisão | M2: ='Dados Empresa'!Q3 -> 11
L3: Data da Revisão | M3: ='Dados Empresa'!Q4 -> 45478
B4: RA: | F4: FORMATO ELETRÔNICO PARA IMPORTAÇÃO
B5: Campos marcados com (*) são obrigatórios para solicitação de análise. Se o cliente não desejar informar o a vazão e o volume da amostragem, o mesmo pode optar por receber o resultado do relatório de análise em massa.
B6: O prazo de entrega dos resultados será contado a partir do recebimento das informações obrigatórias.
B7: Para varredura e naftas, o laboratório determinará os agentes de acordo com a planilha "Informações"
B8: Amostras enviadas sem as informações obrigatórias serão descartadas após 30 dias e será cobrado o custo dos amostradores.
B10: (*) NÚMERO DO AMOSTRADOR (CLIENTE) | C10: (*) DATA AMOSTRAGEM | D10: (*) NÚMERO DO AMOSTRADOR | E10: CÓD. BRANCO CAMPO | F10: NOME DO FUNCIONÁRIO | G10: FUNÇÃO | H10: SETOR | I10: TÉCNICO RESPONSÁVEL PELA AMOSTRAGEM | J10: VAZÃO MÉDIA (L/min) | K10: VOLUME AMOSTRADO (Litros) | L10: INÍCIO DA AMOSTRAGEM (Hora) | M10: TÉRMINO DA AMOSTRAGEM (Hora) | N10: INíCIO DO INTERVALO (Hora) | O10: TÉRMINO DO INTERVALO (Hora) | P10: OBSERVAÇÕES | Q10: (*) AGENTE 1 | R10: (*) AGENTE 2 | S10: (*) AGENTE 3 | T10: (*) AGENTE 4 | U10: (*) AGENTE 5 | V10: (*) AGENTE 6 | W10: (*) AGENTE 7 | X10: (*) AGENTE 8 | Y10: (*) AGENTE 9 | Z10: (*) AGENTE 10
A11: Descarte | J11: 1.7 | K11: =(IF(M11>L11,M11-L11,("04/10/2024 " & TEXT(M11,"HH:MM"))-("03/10/2024 " & TEXT(L11,"HH:MM")))-IF(O11>N11,(O11-N11),IF(O11-N11=0,0,("04/10/2024 " & TEXT(O11,"HH:MM"))-("03/10/2024 " & TEXT(N11,"HH:MM")))))*24*60*J11 -> 102 | L11: 0.83333333 | M11: 0.875
A12: Devolução | K12: =(IF(M12>L12,M12-L12,("04/10/2024 " & TEXT(M12,"HH:MM"))-("03/10/2024 " & TEXT(L12,"HH:MM")))-IF(O12>N12,(O12-N12),IF(O12-N12=0,0,("04/10/2024 " & TEXT(O12,"HH:MM"))-("03/10/2024 " & TEXT(N12,"HH:MM")))))*24*60*J12 -> 0
A13: (SOB CONSULTA) 1,2,4-Triclorobenzeno | K13: =(IF(M13>L13,M13-L13,("04/10/2024 " & TEXT(M13,"HH:MM"))-("03/10/2024 " & TEXT(L13,"HH:MM")))-IF(O13>N13,(O13-N13),IF(O13-N13=0,0,("04/10/2024 " & TEXT(O13,"HH:MM"))-("03/10/2024 " & TEXT(N13,"HH:MM")))))*24*60*J13 -> 0
A14: (SOB CONSULTA) 2-Cianoacrilato de metila « | K14: =(IF(M14>L14,M14-L14,("04/10/2024 " & TEXT(M14,"HH:MM"))-("03/10/2024 " & TEXT(L14,"HH:MM")))-IF(O14>N14,(O14-N14),IF(O14-N14=0,0,("04/10/2024 " & TEXT(O14,"HH:MM"))-("03/10/2024 " & TEXT(N14,"HH:MM")))))*24*60*J14 -> 0
A15: (SOB CONSULTA) 2-Nitropropano « | K15: =(IF(M15>L15,M15-L15,("04/10/2024 " & TEXT(M15,"HH:MM"))-("03/10/2024 " & TEXT(L15,"HH:MM")))-IF(O15>N15,(O15-N15),IF(O15-N15=0,0,("04/10/2024 " & TEXT(O15,"HH:MM"))-("03/10/2024 " & TEXT(N15,"HH:MM")))))*24*60*J15 -> 0
A16: (SOB CONSULTA) Ácido 2-etilhexanóico « | K16: =(IF(M16>L16,M16-L16,("04/10/2024 " & TEXT(M16,"HH:MM"))-("03/10/2024 " & TEXT(L16,"HH:MM")))-IF(O16>N16,(O16-N16),IF(O16-N16=0,0,("04/10/2024 " & TEXT(O16,"HH:MM"))-("03/10/2024 " & TEXT(N16,"HH:MM")))))*24*60*J16 -> 0
A17: (SOB CONSULTA) Brometo de metila | K17: =(IF(M17>L17,M17-L17,("04/10/2024 " & TEXT(M17,"HH:MM"))-("03/10/2024 " & TEXT(L17,"HH:MM")))-IF(O17>N17,(O17-N17),IF(O17-N17=0,0,("04/10/2024 " & TEXT(O17,"HH:MM"))-("03/10/2024 " & TEXT(N17,"HH:MM")))))*24*60*J17 -> 0
A18: (SOB CONSULTA) Diisopropilamina « | K18: =(IF(M18>L18,M18-L18,("04/10/2024 " & TEXT(M18,"HH:MM"))-("03/10/2024 " & TEXT(L18,"HH:MM")))-IF(O18>N18,(O18-N18),IF(O18-N18=0,0,("04/10/2024 " & TEXT(O18,"HH:MM"))-("03/10/2024 " & TEXT(N18,"HH:MM")))))*24*60*J18 -> 0
A19: (SOB CONSULTA) Dissulfeto de Dimetila « | K19: =(IF(M19>L19,M19-L19,("04/10/2024 " & TEXT(M19,"HH:MM"))-("03/10/2024 " & TEXT(L19,"HH:MM")))-IF(O19>N19,(O19-N19),IF(O19-N19=0,0,("04/10/2024 " & TEXT(O19,"HH:MM"))-("03/10/2024 " & TEXT(N19,"HH:MM")))))*24*60*J19 -> 0
A20: (SOB CONSULTA) Enflurano | K20: =(IF(M20>L20,M20-L20,("04/10/2024 " & TEXT(M20,"HH:MM"))-("03/10/2024 " & TEXT(L20,"HH:MM")))-IF(O20>N20,(O20-N20),IF(O20-N20=0,0,("04/10/2024 " & TEXT(O20,"HH:MM"))-("03/10/2024 " & TEXT(N20,"HH:MM")))))*24*60*J20 -> 0
A21: (SOB CONSULTA) Éter metil terc-butílico | K21: =(IF(M21>L21,M21-L21,("04/10/2024 " & TEXT(M21,"HH:MM"))-("03/10/2024 " & TEXT(L21,"HH:MM")))-IF(O21>N21,(O21-N21),IF(O21-N21=0,0,("04/10/2024 " & TEXT(O21,"HH:MM"))-("03/10/2024 " & TEXT(N21,"HH:MM")))))*24*60*J21 -> 0
A22: (SOB CONSULTA) Etil amil cetona « | K22: =(IF(M22>L22,M22-L22,("04/10/2024 " & TEXT(M22,"HH:MM"))-("03/10/2024 " & TEXT(L22,"HH:MM")))-IF(O22>N22,(O22-N22),IF(O22-N22=0,0,("04/10/2024 " & TEXT(O22,"HH:MM"))-("03/10/2024 " & TEXT(N22,"HH:MM")))))*24*60*J22 -> 0
A23: (SOB CONSULTA) Furfural « | K23: =(IF(M23>L23,M23-L23,("04/10/2024 " & TEXT(M23,"HH:MM"))-("03/10/2024 " & TEXT(L23,"HH:MM")))-IF(O23>N23,(O23-N23),IF(O23-N23=0,0,("04/10/2024 " & TEXT(O23,"HH:MM"))-("03/10/2024 " & TEXT(N23,"HH:MM")))))*24*60*J23 -> 0
... A478: Zircônio e compostos, como Zr | K478: =(IF(M478>L478,M478-L478,("04/10/2024 " & TEXT(M478,"HH:MM"))-("03/10/2024 " & TEXT(L478,"HH:MM")))-IF(O478>N478,(O478-N478),IF(O478-N478=0,0,("04/10/2024 " & TEXT(O478,"HH:MM"))-("03/10/2024 " & TEXT(N478,"HH:MM")))))*24*60*J478 -> 0
K479: =(IF(M479>L479,M479-L479,("04/10/2024 " & TEXT(M479,"HH:MM"))-("03/10/2024 " & TEXT(L479,"HH:MM")))-IF(O479>N479,(O479-N479),IF(O479-N479=0,0,("04/10/2024 " & TEXT(O479,"HH:MM"))-("03/10/2024 " & TEXT(N479,"HH:MM")))))*24*60*J479 -> 0
K480: =(IF(M480>L480,M480-L480,("04/10/2024 " & TEXT(M480,"HH:MM"))-("03/10/2024 " & TEXT(L480,"HH:MM")))-IF(O480>N480,(O480-N480),IF(O480-N480=0,0,("04/10/2024 " & TEXT(O480,"HH:MM"))-("03/10/2024 " & TEXT(N480,"HH:MM")))))*24*60*J480 -> 0
K481: =(IF(M481>L481,M481-L481,("04/10/2024 " & TEXT(M481,"HH:MM"))-("03/10/2024 " & TEXT(L481,"HH:MM")))-IF(O481>N481,(O481-N481),IF(O481-N481=0,0,("04/10/2024 " & TEXT(O481,"HH:MM"))-("03/10/2024 " & TEXT(N481,"HH:MM")))))*24*60*J481 -> 0
K482: =(IF(M482>L482,M482-L482,("04/10/2024 " & TEXT(M482,"HH:MM"))-("03/10/2024 " & TEXT(L482,"HH:MM")))-IF(O482>N482,(O482-N482),IF(O482-N482=0,0,("04/10/2024 " & TEXT(O482,"HH:MM"))-("03/10/2024 " & TEXT(N482,"HH:MM")))))*24*60*J482 -> 0
K483: =(IF(M483>L483,M483-L483,("04/10/2024 " & TEXT(M483,"HH:MM"))-("03/10/2024 " & TEXT(L483,"HH:MM")))-IF(O483>N483,(O483-N483),IF(O483-N483=0,0,("04/10/2024 " & TEXT(O483,"HH:MM"))-("03/10/2024 " & TEXT(N483,"HH:MM")))))*24*60*J483 -> 0
K484: =(IF(M484>L484,M484-L484,("04/10/2024 " & TEXT(M484,"HH:MM"))-("03/10/2024 " & TEXT(L484,"HH:MM")))-IF(O484>N484,(O484-N484),IF(O484-N484=0,0,("04/10/2024 " & TEXT(O484,"HH:MM"))-("03/10/2024 " & TEXT(N484,"HH:MM")))))*24*60*J484 -> 0
K485: =(IF(M485>L485,M485-L485,("04/10/2024 " & TEXT(M485,"HH:MM"))-("03/10/2024 " & TEXT(L485,"HH:MM")))-IF(O485>N485,(O485-N485),IF(O485-N485=0,0,("04/10/2024 " & TEXT(O485,"HH:MM"))-("03/10/2024 " & TEXT(N485,"HH:MM")))))*24*60*J485 -> 0
K486: =(IF(M486>L486,M486-L486,("04/10/2024 " & TEXT(M486,"HH:MM"))-("03/10/2024 " & TEXT(L486,"HH:MM")))-IF(O486>N486,(O486-N486),IF(O486-N486=0,0,("04/10/2024 " & TEXT(O486,"HH:MM"))-("03/10/2024 " & TEXT(N486,"HH:MM")))))*24*60*J486 -> 0
K487: =(IF(M487>L487,M487-L487,("04/10/2024 " & TEXT(M487,"HH:MM"))-("03/10/2024 " & TEXT(L487,"HH:MM")))-IF(O487>N487,(O487-N487),IF(O487-N487=0,0,("04/10/2024 " & TEXT(O487,"HH:MM"))-("03/10/2024 " & TEXT(N487,"HH:MM")))))*24*60*J487 -> 0
K488: =(IF(M488>L488,M488-L488,("04/10/2024 " & TEXT(M488,"HH:MM"))-("03/10/2024 " & TEXT(L488,"HH:MM")))-IF(O488>N488,(O488-N488),IF(O488-N488=0,0,("04/10/2024 " & TEXT(O488,"HH:MM"))-("03/10/2024 " & TEXT(N488,"HH:MM")))))*24*60*J488 -> 0
K489: =(IF(M489>L489,M489-L489,("04/10/2024 " & TEXT(M489,"HH:MM"))-("03/10/2024 " & TEXT(L489,"HH:MM")))-IF(O489>N489,(O489-N489),IF(O489-N489=0,0,("04/10/2024 " & TEXT(O489,"HH:MM"))-("03/10/2024 " & TEXT(N489,"HH:MM")))))*24*60*J489 -> 0
K490: =(IF(M490>L490,M490-L490,("04/10/2024 " & TEXT(M490,"HH:MM"))-("03/10/2024 " & TEXT(L490,"HH:MM")))-IF(O490>N490,(O490-N490),IF(O490-N490=0,0,("04/10/2024 " & TEXT(O490,"HH:MM"))-("03/10/2024 " & TEXT(N490,"HH:MM")))))*24*60*J490 -> 0

Sheet Informações Adicionais
E1: FORMULÁRIO PARA SOLICITAÇÃO DE ANÁLISE DE AMOSTRAS DE HIGIENE OCUPACIONAL | H1: Código: | I1: ='Dados Empresa'!Q2 -> IT02-M
H2: Revisão: | I2: ='Dados Empresa'!Q3 -> 11
H3: Data Revisão: | I3: ='Dados Empresa'!Q4 -> 45478
B4: FORMATO ELETRÔNICO PARA IMPORTAÇÃO
D6: Varredura de Metais (20 agentes)
D7: Agentes que serão determinados: | G7: Método: | H7: NIOSH 7303
D8: Alumínio metal e compostos insolúveis
D9: Antimônio e compostos, como Sb
D10: Bário e compostos solúveis, como Ba
D11: Óxido de Boro
D12: Cádmio e compostos
D13: Óxido de Cálcio
D14: Chumbo e compostos inorgânicos, como Pb
D15: Cobalto e compostos inorgânicos, como Co
D16: Cobre, fumos como Cu
D17: Cromo metálico, como Cr(0)
D18: Estanho e compostos inorgânicos excluindo hidreto de Sn, como Sn
D19: Ferro, óxido
... D29: Varredura de Metais (Fração Total)
D30: Agentes que serão determinados: | G30: Método: | H30: NIOSH 7303
D31: Antimônio e compostos, como Sb
D32: Cádmio
D33: Chumbo e compostos inorgânicos, como Pb
D34: Cobre, fumos como Cu
D35: Estanho, compostos orgânicos como estanho
D36: Manganês e seus compostos
D37: Óxido de boro
D38: Óxido de cálcio
D40: Varredura de Metais (Fração Respirável)
D41: Agentes que serão determinados: | G41: Método: | H41: NIOSH 7303
D42: Alumínio metal e compostos insolúveis
D43: Cádmio e compostos, como Cd
D44: Ferro, óxido (Fe2O3)
D45: Manganês, elementar
D46: Molibdênio, como Mo, compostos solúveis
D47: Óxido de zinco
D48: Dióxido de titânio (Partículas finas)
D50: Varredura de Metais (Fração Inalável)
D51: Agentes que serão determinados: | G51: Método: | H51: NIOSH 7303
D52: Cromo metálico, como Cr(0)
...

Sheet Plan1
A1: 1,1,2,2-Tetracloroetano
A2: 1,1,2-Tricloroetano (SOB CONSULTA)«
A3: 1,1-Dicloroetano
A4: 1,2-Dicloroetileno, todos os isômeros
A5: 1,3,5-Triglicidil isocianurato «
A6: 1,3-Butadieno
A7: 1,4-Dioxano «
A8: 1-Metil naftaleno e 2-Metil naftaleno
A9: 1-Metoxi-2-propanol
A10: 2,4-D «
A11: 2-Butóxi etanol (EGBE)
A12: 2-Etoxietanol
... A386: Zircônio e compostos, como Zr
